Workbook

Sheet README
B2: Vietnam: who contributes to the state budget, financial year 2025
B4: Reading the list years
B5: CafeF labels a list by its PUBLICATION year, not the year of the payments.
B6: The lists published in 2026 measure amounts actually remitted in financial year 2025.
B7: This workbook uses those 2026-published lists throughout. A list labelled 2025 would be FY2024.
B8: Cross-check: PetroVietnam is VND 90,991 bn in both the 2026 VNTAX 200 and the STATE 100.
B10: Sources
B11: VNTAX 200: https://cafef.vn/du-lieu/vntax200/2026/top-200-doanh-nghiep.chn
B12: STATE 100: https://cafef.vn/du-lieu/state100/doanh-nghiep.chn
B13: PRIVATE 100: https://cafef.vn/du-lieu/private100/2026/top-100-doanh-nghiep.chn
B14: National outturn: GSO / Ministry of Finance, FY2025 revenue = VND 2,650.1 trillion.
B15: Units
... B49: Analysis prepared 4 September 2026.

Sheet Firm level
A1: Rank | B1: Enterprise (VN) | C1: Trading name | D1: Code | E1: Ownership | F1: Sector | G1: Sector (source, VN) | H1: Budget payment (VND bn) | I1: Share of list | J1: Ownership basis / note | K1: VAT domestic | L1: VAT imports | M1: Corporate income tax | N1: Personal income tax | O1: Land & land rent
A2: 1 | B2: Tập đoàn Vingroup - Công ty Cổ phần | C2: Vingroup | D2: VIC | E2: Private | F2: Real estate & construction | G2: Bất động sản, Ô tô | H2: 148773 | I2: =H2/$H$202 -> 0.15038908 | J2: CafeF PRIVATE 100 (2026) | K2: 23183 | M2: 17043 | N2: 5057 | O2: 93813
A3: 2 | B3: Tập đoàn Công nghiệp - Năng lượng Quốc gia Việt Nam | C3: PetroVietnam | D3: PVN | E3: SOE | F3: Oil, gas & fuels | G3: Dầu khí | H3: 90991 | I3: =H3/$H$202 -> 0.091979411 | J3: CafeF STATE 100 (2026) | K3: 12585 | L3: 8648 | M3: 14599 | N3: 1865
A4: 3 | B4: Tập đoàn Công nghiệp - Viễn thông Quân đội (Viettel) | C4: Viettel | D4: VIETTEL | E4: SOE | F4: Technology & telecom | G4: Công nghệ - Viễn thông - Truyền thông | H4: 42290 | I4: =H4/$H$202 -> 0.042749385 | J4: CafeF STATE 100 (2026)
A5: 4 | B5: Tập đoàn Xăng dầu Việt Nam | C5: Petrolimex | D5: PLX | E5: SOE | F5: Oil, gas & fuels | G5: Xăng dầu - khí đốt | H5: 30575 | I5: =H5/$H$202 -> 0.030907128 | J5: CafeF STATE 100 (2026) | K5: 3055 | L5: 6397 | M5: 727 | N5: 320
A6: 5 | B6: Công ty TNHH Nhà máy Bia Heineken Việt Nam | C6: Heineken Vietnam | D6: HEINEKEN | E6: FDI | F6: Food, beverage & brewing | G6: Bia rượu | H6: 27000 | I6: =H6/$H$202 -> 0.027293294 | J6: Heineken NV, foreign-controlled JV
A7: 6 | B7: Công ty Ô tô Toyota Việt Nam | C7: Toyota Vietnam | D7: TOYOTAVN | E7: FDI | F7: Automotive | G7: Ô tô | H7: 26000 | I7: =H7/$H$202 -> 0.026282431 | J7: Toyota (JP)
A8: 7 | B8: Công ty Cổ phần Tập đoàn Sunshine | C8: Sunshine Group | D8: KSF | E8: Private | F8: Real estate & construction | G8: Bất động sản - Xây dựng | H8: 24045 | I8: =H8/$H$202 -> 0.024306194 | J8: CafeF PRIVATE 100 (2026)
A9: 8 | B9: Tập đoàn Công nghiệp Than - Khoáng sản Việt Nam | C9: Vinacomin | D9: VINACOMIN | E9: SOE | F9: Coal & mining | G9: Than, Khoáng sản | H9: 24031 | I9: =H9/$H$202 -> 0.024292042 | J9: CafeF STATE 100 (2026) | K9: 3746 | L9: 2281 | M9: 1732 | O9: 423
A10: 9 | B10: Công ty TNHH Lọc hóa dầu Nghi Sơn | C10: NSRP | D10: NSRP | E10: FDI | F10: Oil, gas & fuels | G10: Dầu khí | H10: 23000 | I10: =H10/$H$202 -> 0.023249843 | J10: Idemitsu + KPI 70.2%, PVN 25.1%
A11: 10 | B11: Tổng Công ty Thuốc lá Việt Nam - Công ty TNHH MTV | C11: Vinataba | D11: VINATABA | E11: SOE | F11: Tobacco | G11: Thuốc lá | H11: 22335 | I11: =H11/$H$202 -> 0.022577619 | J11: CafeF STATE 100 (2026) | K11: 3546 | M11: 418
A12: 11 | B12: Liên doanh Việt - Nga Vietsovpetro | C12: Vietsovpetro | D12: VIETSOVPETRO | E12: SOE | F12: Oil, gas & fuels | G12: Dầu khí | H12: 21450 | I12: =H12/$H$202 -> 0.021683006 | J12: PVN 51% / Zarubezhneft 49%, state-controlled JV
A13: 12 | B13: CTCP Tập đoàn Trường Hải | C13: Thaco Group | D13: THA | E13: Private | F13: Automotive | G13: Ô tô | H13: 21158 | I13: =H13/$H$202 -> 0.021387834 | J13: CafeF PRIVATE 100 (2026)
A14: 13 | B14: Tập đoàn Điện lực Việt Nam - Công ty TNHH MTV | C14: EVN | D14: EVN | E14: SOE | F14: Power & electrical | G14: Điện năng | H14: 20891 | I14: =H14/$H$202 -> 0.021117933 | J14: CafeF STATE 100 (2026) | K14: 8367 | M14: 1201 | N14: 1163
A15: 14 | B15: Tổng CTCP Bia - Rượu - Nước giải khát Sài Gòn | C15: Sabeco | D15: SAB | E15: FDI | F15: Food, beverage & brewing | G15: Bia rượu | H15: 14917 | I15: =H15/$H$202 -> 0.015079039 | J15: ThaiBev 53.6%; MOIT 36% | K15: 2118 | M15: 1057 | N15: 120
A16: 15 | B16: Công ty TNHH Phát Triển Khu đô thị Nam Thăng Long | C16: Ciputra Hanoi | D16: CIPUTRAHN | E16: FDI | F16: Real estate & construction | G16: Bất động sản - Xây dựng | H16: 13600 | I16: =H16/$H$202 -> 0.013747733 | J16: Ciputra (ID) led JV with UDIC
A17: 16 | B17: Công ty Cổ phần Đầu tư phát triển Thành phố Thông minh Bắc Hà Nội | C17: NH Smart City | D17: NHSC | E17: Private | F17: Real estate & construction | G17: Bất động sản - Xây dựng | H17: 13171 | I17: =H17/$H$202 -> 0.013314073 | J17: CafeF PRIVATE 100 (2026)
A18: 17 | B18: Công ty cổ phần Tập đoàn Hòa Phát | C18: Hòa Phát Group | D18: HPG | E18: Private | F18: Steel & building materials | G18: Thép | H18: 12954 | I18: =H18/$H$202 -> 0.013094716 | J18: CafeF PRIVATE 100 (2026) | K18: 903 | L18: 8766 | M18: 1995 | N18: 211
A19: 18 | B19: Ngân hàng Thương mại cổ phần Ngoại thương Việt Nam | C19: Vietcombank | D19: VCB | E19: SOE | F19: Banking | G19: Ngân hàng | H19: 12494 | I19: =H19/$H$202 -> 0.012629719 | J19: CafeF STATE 100 (2026) | K19: 835 | M19: 9242
A20: 19 | B20: Tập đoàn Thành Công (TC Group) | C20: Thành Công Group | D20: TCGROUP | E20: Private | F20: Automotive | G20: Ô tô, Bất động sản | H20: 12441 | I20: =H20/$H$202 -> 0.012576143 | J20: CafeF PRIVATE 100 (2026)
A21: 20 | B21: Công ty Honda Việt Nam | C21: Honda Vietnam | D21: HONDA | E21: FDI | F21: Automotive | G21: Ô tô | H21: 11880 | I21: =H21/$H$202 -> 0.012009049 | J21: Honda (JP)
A22: 21 | B22: Ngân hàng Thương mại cổ phần Đầu tư và Phát triển Việt Nam | C22: BIDV | D22: BID | E22: SOE | F22: Banking | G22: Ngân hàng | H22: 11374 | I22: =H22/$H$202 -> 0.011497553 | J22: CafeF STATE 100 (2026) | K22: 1430 | M22: 6768
A23: 22 | B23: Công ty TNHH Ford Việt Nam | C23: Ford Vietnam | D23: FORDVN | E23: FDI | F23: Automotive | G23: Ô tô | H23: 11300 | I23: =H23/$H$202 -> 0.011422749 | J23: Ford (US)
A24: 23 | B24: Công ty Cổ phần FPT | C24: FPT | D24: FPT | E24: Private | F24: Technology & telecom | G24: Công nghệ - Viễn thông - Truyền thông | H24: 11291 | I24: =H24/$H$202 -> 0.011413651 | J24: CafeF PRIVATE 100 (2026) | K24: 6437 | M24: 2238 | N24: 2182
A25: 24 | B25: Ngân hàng TMCP Kỹ Thương Việt Nam | C25: Techcombank | D25: TCB | E25: Private | F25: Banking | G25: Ngân hàng | H25: 10984 | I25: =H25/$H$202 -> 0.011103316 | J25: CafeF PRIVATE 100 (2026) | K25: 760 | M25: 7178
A26: 25 | B26: Ngân hàng Thương mại Cổ phần Công thương Việt Nam | C26: Vietinbank | D26: CTG | E26: SOE | F26: Banking | G26: Ngân hàng | H26: 10057 | I26: =H26/$H$202 -> 0.010166246 | J26: CafeF STATE 100 (2026) | K26: 998 | M26: 7541
A27: 26 | B27: Ngân hàng Thương mại cổ phần Quân đội | C27: MB | D27: MBB | E27: SOE | F27: Banking | G27: Ngân hàng | H27: 10004 | I27: =H27/$H$202 -> 0.010112671 | J27: CafeF STATE 100 (2026) | K27: 1105 | M27: 6518
A28: 27 | B28: Tổng Công ty Đầu tư và Kinh doanh vốn Nhà nước | C28: SCIC | D28: SCIC | E28: SOE | F28: Finance & investment | G28: Đầu tư | H28: 8404 | I28: =H28/$H$202 -> 0.0084952904 | J28: CafeF STATE 100 (2026) | M28: 384
A29: 28 | B29: Ngân hàng Nông nghiệp và Phát triển Nông thôn Việt Nam | C29: Agribank | D29: AGRIBANK | E29: SOE | F29: Banking | G29: Ngân hàng | H29: 7854 | I29: =H29/$H$202 -> 0.0079393159 | J29: CafeF STATE 100 (2026) | K29: 763 | M29: 5658
A30: 29 | B30: Ngân hàng Thương mại Cổ phần Việt Nam Thịnh Vượng | C30: VPBank | D30: VPB | E30: Private | F30: Banking | G30: Ngân hàng | H30: 6883 | I30: =H30/$H$202 -> 0.0069577682 | J30: CafeF PRIVATE 100 (2026) | K30: 879 | M30: 4128
A31: 30 | B31: Công ty Đầu tư Tài chính Nhà nước T.P Hồ Chí Minh | C31: HFIC | D31: HFIC | E31: SOE | F31: Finance & investment | G31: Đầu tư | H31: 6794 | I31: =H31/$H$202 -> 0.0068678014 | J31: CafeF STATE 100 (2026) | K31: 1441 | M31: 683 | N31: 500 | O31: 339
A32: 31 | B32: Tập đoàn Bưu chính Viễn thông Việt Nam | C32: VNPT | D32: VNPT | E32: SOE | F32: Technology & telecom | G32: Công nghệ - Viễn thông - Truyền thông | H32: 6078 | I32: =H32/$H$202 -> 0.0061440237 | J32: CafeF STATE 100 (2026)
A33: 32 | B33: Ngân hàng Thương Mại Cổ Phần Á Châu | C33: ACB | D33: ACB | E33: Private | F33: Banking | G33: Ngân hàng | H33: 5782 | I33: =H33/$H$202 -> 0.0058448083 | J33: CafeF PRIVATE 100 (2026) | K33: 452 | M33: 4335
A34: 33 | B34: Tổng Công ty Cổ phần Đầu tư Xây dựng và Thương mại Việt Nam | C34: CTX Holdings | D34: CTX | E34: Private | F34: Real estate & construction | G34: Bất động sản - Xây dựng | H34: 5127 | I34: =H34/$H$202 -> 0.0051826932 | J34: CafeF PRIVATE 100 (2026) | K34: 76 | M34: 3 | O34: 4970
A35: 34 | B35: Tổng công ty Cảng hàng không Việt Nam - CTCP | C35: ACV | D35: ACV | E35: SOE | F35: Aviation | G35: Hàng không | H35: 4656 | I35: =H35/$H$202 -> 0.0047065769 | J35: CafeF STATE 100 (2026) | K35: 211 | M35: 2582 | N35: 403 | O35: 149
A36: 35 | B36: Công ty Cổ phần Tập đoàn MaSan | C36: Masan Group | D36: MSN | E36: Private | F36: Food, beverage & brewing | G36: Thực phẩm, Bán lẻ, Tài chính | H36: 4636 | I36: =H36/$H$202 -> 0.0046863596 | J36: CafeF PRIVATE 100 (2026) | K36: 1854 | M36: 1274 | N36: 393
A37: 36 | B37: Ngân hàng Thương mại Cổ phần Sài Gòn Tài Lộc | C37: Sacombank | D37: STB | E37: Private | F37: Banking | G37: Ngân hàng | H37: 4304 | I37: =H37/$H$202 -> 0.0043507532 | J37: CafeF PRIVATE 100 (2026) | K37: 830 | M37: 2773
A38: 37 | B38: Tổng Công ty Khánh Việt | C38: Khatoco | D38: KHATOCO | E38: SOE | F38: Tobacco | G38: Thuốc lá | H38: 4292 | I38: =H38/$H$202 -> 0.0043386228 | J38: CafeF STATE 100 (2026) | K38: 537 | L38: 78 | M38: 58
A39: 38 | B39: Tổng CTCP Bia - Rượu - Nước giải khát Hà Nội | C39: Habeco | D39: BHN | E39: SOE | F39: Food, beverage & brewing | G39: Bia rượu | H39: 4158 | I39: =H39/$H$202 -> 0.0042031672 | J39: CafeF STATE 100 (2026) | K39: 613 | M39: 155
A40: 39 | B40: Công ty Cổ phần Sữa Việt Nam | C40: Vinamilk | D40: VNM | E40: Private | F40: Food, beverage & brewing | G40: Thực phẩm | H40: 3856 | I40: =H40/$H$202 -> 0.0038978867 | J40: CafeF PRIVATE 100 (2026) | K40: 1777 | M40: 1536 | N40: 311
...

Sheet By ownership
A1: Budget remittance by ownership, VNTAX 200, financial year 2025
A3: Ownership | B3: Firms | C3: Budget payment (VND bn) | D3: Share of list | E3: Share of national revenue | F3: Average per firm
A4: State-owned (SOE) | B4: =COUNTIF('Firm level'!$E$2:$E$201,"SOE") -> 74 | C4: =SUMIF('Firm level'!$E$2:$E$201,"SOE",'Firm level'!$H$2:$H$201) -> 445558 | D4: =C4/$C$7 -> 0.45039798 | E4: =C4/$B$10 -> 0.16812875 | F4: =C4/B4 -> 6021.0541
A5: Domestic private | B5: =COUNTIF('Firm level'!$E$2:$E$201,"Private") -> 99 | C5: =SUMIF('Firm level'!$E$2:$E$201,"Private",'Firm level'!$H$2:$H$201) -> 390311 | D5: =C5/$C$7 -> 0.39455084 | E5: =C5/$B$10 -> 0.14728161 | F5: =C5/B5 -> 3942.5354
A6: Foreign-invested (FDI) | B6: =COUNTIF('Firm level'!$E$2:$E$201,"FDI") -> 27 | C6: =SUMIF('Firm level'!$E$2:$E$201,"FDI",'Firm level'!$H$2:$H$201) -> 153385 | D6: =C6/$C$7 -> 0.15505118 | E6: =C6/$B$10 -> 0.057878948 | F6: =C6/B6 -> 5680.9259
A7: TOTAL, VNTAX 200 | B7: =SUM(B4:B6) -> 200 | C7: =SUM(C4:C6) -> 989254 | D7: =C7/$C$7 -> 1 | E7: =C7/$B$10 -> 0.37328931 | F7: =C7/B7 -> 4946.27
A10: Memo: total state budget revenue, FY2025 (VND bn) | B10: 2650100 | C10: Hardcoded input. Source: GSO/MoF FY2025 outturn, VND 2,650.1 trillion.
A12: State-owned | B12: =C4 -> 445558 | C12: =B12/$C$7 -> 0.45039798
A13: Non-state (private + FDI) | B13: =C5+C6 -> 543696 | C13: =B13/$C$7 -> 0.54960202

Sheet By sector
A1: Budget remittance by sector and ownership, financial year 2025
A3: Sector | B3: Firms | C3: SOE | D3: Domestic private | E3: FDI | F3: Total (VND bn) | G3: Share of list | H3: SOE share of sector
A4: Real estate & construction | B4: =COUNTIF('Firm level'!$F$2:$F$201,$A4) -> 32 | C4: =SUMIFS('Firm level'!$H$2:$H$201,'Firm level'!$F$2:$F$201,$A4,'Firm level'!$E$2:$E$201,"SOE") -> 5228 | D4: =SUMIFS('Firm level'!$H$2:$H$201,'Firm level'!$F$2:$F$201,$A4,'Firm level'!$E$2:$E$201,"Private") -> 213029 | E4: =SUMIFS('Firm level'!$H$2:$H$201,'Firm level'!$F$2:$F$201,$A4,'Firm level'!$E$2:$E$201,"FDI") -> 16577 | F4: =SUM(C4:E4) -> 234834 | G4: =F4/$F$26 -> 0.23738494 | H4: =IF(F4=0,"",C4/F4) -> 0.022262534
A5: Oil, gas & fuels | B5: =COUNTIF('Firm level'!$F$2:$F$201,$A5) -> 7 | C5: =SUMIFS('Firm level'!$H$2:$H$201,'Firm level'!$F$2:$F$201,$A5,'Firm level'!$E$2:$E$201,"SOE") -> 145800 | D5: =SUMIFS('Firm level'!$H$2:$H$201,'Firm level'!$F$2:$F$201,$A5,'Firm level'!$E$2:$E$201,"Private") -> 3468 | E5: =SUMIFS('Firm level'!$H$2:$H$201,'Firm level'!$F$2:$F$201,$A5,'Firm level'!$E$2:$E$201,"FDI") -> 23000 | F5: =SUM(C5:E5) -> 172268 | G5: =F5/$F$26 -> 0.1741393 | H5: =IF(F5=0,"",C5/F5) -> 0.84635568
A6: Banking | B6: =COUNTIF('Firm level'!$F$2:$F$201,$A6) -> 23 | C6: =SUMIFS('Firm level'!$H$2:$H$201,'Firm level'!$F$2:$F$201,$A6,'Firm level'!$E$2:$E$201,"SOE") -> 51783 | D6: =SUMIFS('Firm level'!$H$2:$H$201,'Firm level'!$F$2:$F$201,$A6,'Firm level'!$E$2:$E$201,"Private") -> 52126 | E6: =SUMIFS('Firm level'!$H$2:$H$201,'Firm level'!$F$2:$F$201,$A6,'Firm level'!$E$2:$E$201,"FDI") -> 694 | F6: =SUM(C6:E6) -> 104603 | G6: =F6/$F$26 -> 0.10573927 | H6: =IF(F6=0,"",C6/F6) -> 0.49504316
A7: Automotive | B7: =COUNTIF('Firm level'!$F$2:$F$201,$A7) -> 13 | C7: =SUMIFS('Firm level'!$H$2:$H$201,'Firm level'!$F$2:$F$201,$A7,'Firm level'!$E$2:$E$201,"SOE") -> 468 | D7: =SUMIFS('Firm level'!$H$2:$H$201,'Firm level'!$F$2:$F$201,$A7,'Firm level'!$E$2:$E$201,"Private") -> 39684 | E7: =SUMIFS('Firm level'!$H$2:$H$201,'Firm level'!$F$2:$F$201,$A7,'Firm level'!$E$2:$E$201,"FDI") -> 53180 | F7: =SUM(C7:E7) -> 93332 | G7: =F7/$F$26 -> 0.09434584 | H7: =IF(F7=0,"",C7/F7) -> 0.0050143573
A8: Food, beverage & brewing | B8: =COUNTIF('Firm level'!$F$2:$F$201,$A8) -> 19 | C8: =SUMIFS('Firm level'!$H$2:$H$201,'Firm level'!$F$2:$F$201,$A8,'Firm level'!$E$2:$E$201,"SOE") -> 4693 | D8: =SUMIFS('Firm level'!$H$2:$H$201,'Firm level'!$F$2:$F$201,$A8,'Firm level'!$E$2:$E$201,"Private") -> 16105 | E8: =SUMIFS('Firm level'!$H$2:$H$201,'Firm level'!$F$2:$F$201,$A8,'Firm level'!$E$2:$E$201,"FDI") -> 45917 | F8: =SUM(C8:E8) -> 66715 | G8: =F8/$F$26 -> 0.067439707 | H8: =IF(F8=0,"",C8/F8) -> 0.070344001
A9: Technology & telecom | B9: =COUNTIF('Firm level'!$F$2:$F$201,$A9) -> 8 | C9: =SUMIFS('Firm level'!$H$2:$H$201,'Firm level'!$F$2:$F$201,$A9,'Firm level'!$E$2:$E$201,"SOE") -> 49868 | D9: =SUMIFS('Firm level'!$H$2:$H$201,'Firm level'!$F$2:$F$201,$A9,'Firm level'!$E$2:$E$201,"Private") -> 14363 | E9: =SUMIFS('Firm level'!$H$2:$H$201,'Firm level'!$F$2:$F$201,$A9,'Firm level'!$E$2:$E$201,"FDI") -> 1000 | F9: =SUM(C9:E9) -> 65231 | G9: =F9/$F$26 -> 0.065939587 | H9: =IF(F9=0,"",C9/F9) -> 0.76448314
A10: Lottery | B10: =COUNTIF('Firm level'!$F$2:$F$201,$A10) -> 21 | C10: =SUMIFS('Firm level'!$H$2:$H$201,'Firm level'!$F$2:$F$201,$A10,'Firm level'!$E$2:$E$201,"SOE") -> 53499 | D10: =SUMIFS('Firm level'!$H$2:$H$201,'Firm level'!$F$2:$F$201,$A10,'Firm level'!$E$2:$E$201,"Private") -> 0 | E10: =SUMIFS('Firm level'!$H$2:$H$201,'Firm level'!$F$2:$F$201,$A10,'Firm level'!$E$2:$E$201,"FDI") -> 0 | F10: =SUM(C10:E10) -> 53499 | G10: =F10/$F$26 -> 0.054080145 | H10: =IF(F10=0,"",C10/F10) -> 1
A11: Power & electrical | B11: =COUNTIF('Firm level'!$F$2:$F$201,$A11) -> 7 | C11: =SUMIFS('Firm level'!$H$2:$H$201,'Firm level'!$F$2:$F$201,$A11,'Firm level'!$E$2:$E$201,"SOE") -> 20891 | D11: =SUMIFS('Firm level'!$H$2:$H$201,'Firm level'!$F$2:$F$201,$A11,'Firm level'!$E$2:$E$201,"Private") -> 11459 | E11: =SUMIFS('Firm level'!$H$2:$H$201,'Firm level'!$F$2:$F$201,$A11,'Firm level'!$E$2:$E$201,"FDI") -> 0 | F11: =SUM(C11:E11) -> 32350 | G11: =F11/$F$26 -> 0.032701409 | H11: =IF(F11=0,"",C11/F11) -> 0.64578053
A12: Tobacco | B12: =COUNTIF('Firm level'!$F$2:$F$201,$A12) -> 4 | C12: =SUMIFS('Firm level'!$H$2:$H$201,'Firm level'!$F$2:$F$201,$A12,'Firm level'!$E$2:$E$201,"SOE") -> 31720 | D12: =SUMIFS('Firm level'!$H$2:$H$201,'Firm level'!$F$2:$F$201,$A12,'Firm level'!$E$2:$E$201,"Private") -> 0 | E12: =SUMIFS('Firm level'!$H$2:$H$201,'Firm level'!$F$2:$F$201,$A12,'Firm level'!$E$2:$E$201,"FDI") -> 0 | F12: =SUM(C12:E12) -> 31720 | G12: =F12/$F$26 -> 0.032064566 | H12: =IF(F12=0,"",C12/F12) -> 1
A13: Coal & mining | B13: =COUNTIF('Firm level'!$F$2:$F$201,$A13) -> 3 | C13: =SUMIFS('Firm level'!$H$2:$H$201,'Firm level'!$F$2:$F$201,$A13,'Firm level'!$E$2:$E$201,"SOE") -> 26475 | D13: =SUMIFS('Firm level'!$H$2:$H$201,'Firm level'!$F$2:$F$201,$A13,'Firm level'!$E$2:$E$201,"Private") -> 748 | E13: =SUMIFS('Firm level'!$H$2:$H$201,'Firm level'!$F$2:$F$201,$A13,'Firm level'!$E$2:$E$201,"FDI") -> 0 | F13: =SUM(C13:E13) -> 27223 | G13: =F13/$F$26 -> 0.027518716 | H13: =IF(F13=0,"",C13/F13) -> 0.97252323
A14: Finance & investment | B14: =COUNTIF('Firm level'!$F$2:$F$201,$A14) -> 5 | C14: =SUMIFS('Firm level'!$H$2:$H$201,'Firm level'!$F$2:$F$201,$A14,'Firm level'!$E$2:$E$201,"SOE") -> 19083 | D14: =SUMIFS('Firm level'!$H$2:$H$201,'Firm level'!$F$2:$F$201,$A14,'Firm level'!$E$2:$E$201,"Private") -> 496 | E14: =SUMIFS('Firm level'!$H$2:$H$201,'Firm level'!$F$2:$F$201,$A14,'Firm level'!$E$2:$E$201,"FDI") -> 0 | F14: =SUM(C14:E14) -> 19579 | G14: =F14/$F$26 -> 0.019791681 | H14: =IF(F14=0,"",C14/F14) -> 0.97466673
A15: Steel & building materials | B15: =COUNTIF('Firm level'!$F$2:$F$201,$A15) -> 9 | C15: =SUMIFS('Firm level'!$H$2:$H$201,'Firm level'!$F$2:$F$201,$A15,'Firm level'!$E$2:$E$201,"SOE") -> 2037 | D15: =SUMIFS('Firm level'!$H$2:$H$201,'Firm level'!$F$2:$F$201,$A15,'Firm level'!$E$2:$E$201,"Private") -> 16315 | E15: =SUMIFS('Firm level'!$H$2:$H$201,'Firm level'!$F$2:$F$201,$A15,'Firm level'!$E$2:$E$201,"FDI") -> 488 | F15: =SUM(C15:E15) -> 18840 | G15: =F15/$F$26 -> 0.019044654 | H15: =IF(F15=0,"",C15/F15) -> 0.10812102
... A25: Textiles | B25: =COUNTIF('Firm level'!$F$2:$F$201,$A25) -> 1 | C25: =SUMIFS('Firm level'!$H$2:$H$201,'Firm level'!$F$2:$F$201,$A25,'Firm level'!$E$2:$E$201,"SOE") -> 895 | D25: =SUMIFS('Firm level'!$H$2:$H$201,'Firm level'!$F$2:$F$201,$A25,'Firm level'!$E$2:$E$201,"Private") -> 0 | E25: =SUMIFS('Firm level'!$H$2:$H$201,'Firm level'!$F$2:$F$201,$A25,'Firm level'!$E$2:$E$201,"FDI") -> 0 | F25: =SUM(C25:E25) -> 895 | G25: =F25/$F$26 -> 0.00090472214 | H25: =IF(F25=0,"",C25/F25) -> 1
A26: TOTAL | B26: =SUM(B4:B25) -> 200 | C26: =SUM(C4:C25) -> 445558 | D26: =SUM(D4:D25) -> 390311 | E26: =SUM(E4:E25) -> 153385 | F26: =SUM(F4:F25) -> 989254 | G26: =F26/$F$26 -> 1 | H26: =C26/F26 -> 0.45039798

Sheet Top 25 firms
A1: Twenty-five largest contributors, financial year 2025
A3: Rank | B3: Enterprise | C3: Ownership | D3: Sector | E3: Budget payment (VND bn) | F3: Cumulative share of list
A4: 1 | B4: Vingroup | C4: Private | D4: Real estate & construction | E4: 148773 | F4: =SUM($E$4:E4)/SUM('Firm level'!$H$2:$H$201) -> 0.15038908
A5: 2 | B5: PetroVietnam | C5: SOE | D5: Oil, gas & fuels | E5: 90991 | F5: =SUM($E$4:E5)/SUM('Firm level'!$H$2:$H$201) -> 0.24236849
A6: 3 | B6: Viettel | C6: SOE | D6: Technology & telecom | E6: 42290 | F6: =SUM($E$4:E6)/SUM('Firm level'!$H$2:$H$201) -> 0.28511788
A7: 4 | B7: Petrolimex | C7: SOE | D7: Oil, gas & fuels | E7: 30575 | F7: =SUM($E$4:E7)/SUM('Firm level'!$H$2:$H$201) -> 0.316025
A8: 5 | B8: Heineken Vietnam | C8: FDI | D8: Food, beverage & brewing | E8: 27000 | F8: =SUM($E$4:E8)/SUM('Firm level'!$H$2:$H$201) -> 0.3433183
A9: 6 | B9: Toyota Vietnam | C9: FDI | D9: Automotive | E9: 26000 | F9: =SUM($E$4:E9)/SUM('Firm level'!$H$2:$H$201) -> 0.36960073
A10: 7 | B10: Sunshine Group | C10: Private | D10: Real estate & construction | E10: 24045 | F10: =SUM($E$4:E10)/SUM('Firm level'!$H$2:$H$201) -> 0.39390692
A11: 8 | B11: Vinacomin | C11: SOE | D11: Coal & mining | E11: 24031 | F11: =SUM($E$4:E11)/SUM('Firm level'!$H$2:$H$201) -> 0.41819897
A12: 9 | B12: NSRP | C12: FDI | D12: Oil, gas & fuels | E12: 23000 | F12: =SUM($E$4:E12)/SUM('Firm level'!$H$2:$H$201) -> 0.44144881
A13: 10 | B13: Vinataba | C13: SOE | D13: Tobacco | E13: 22335 | F13: =SUM($E$4:E13)/SUM('Firm level'!$H$2:$H$201) -> 0.46402643
A14: 11 | B14: Vietsovpetro | C14: SOE | D14: Oil, gas & fuels | E14: 21450 | F14: =SUM($E$4:E14)/SUM('Firm level'!$H$2:$H$201) -> 0.48570943
A15: 12 | B15: Thaco Group | C15: Private | D15: Automotive | E15: 21158 | F15: =SUM($E$4:E15)/SUM('Firm level'!$H$2:$H$201) -> 0.50709727
... A28: 25 | B28: Vietinbank | C28: SOE | D28: Banking | E28: 10057 | F28: =SUM($E$4:E28)/SUM('Firm level'!$H$2:$H$201) -> 0.67626919

Sheet Tax mix
A1: Composition of budget remittance by ownership
A2: Only firms whose component detail is published are included, so rows do not sum to the headline totals.
A4: Ownership | B4: VAT domestic | C4: VAT on imports | D4: Corporate income tax | E4: Personal income tax | F4: Land & land rent | G4: Disclosed total
A5: State-owned (SOE) | B5: 60412 | C5: 17575 | D5: 68850 | E5: 7586 | F5: 4357 | G5: =SUM(B5:F5) -> 158780
A6: Domestic private | B6: 81885 | C6: 12381 | D6: 73890 | E6: 17512 | F6: 107480 | G6: =SUM(B6:F6) -> 293148
A7: Foreign-invested (FDI) | B7: 3337 | C7: 0 | D7: 5045 | E7: 641 | F7: 0 | G7: =SUM(B7:F7) -> 9023
A8: TOTAL | B8: =SUM(B5:B7) -> 145634 | C8: =SUM(C5:C7) -> 29956 | D8: =SUM(D5:D7) -> 147785 | E8: =SUM(E5:E7) -> 25739 | F8: =SUM(F5:F7) -> 111837 | G8: =SUM(G5:G7) -> 460951

Sheet STATE 100 firms
A1: STATE 100 (published 2026, payments made in financial year 2025)
A2: "Counts in group total" is FALSE for the 31 subsidiaries CafeF nets out to avoid double counting.
A4: Rank | B4: Enterprise | C4: Trading name | D4: Code | E4: Sector | F4: Sector (source, VN) | G4: Corporate group | H4: Role | I4: Counts in group total | J4: Budget payment | K4: VAT domestic | L4: VAT imports | M4: Corporate income tax | N4: Personal income tax | O4: Land & land rent | P4: Disclosed detail
A5: 1 | B5: Tập đoàn Công nghiệp - Năng lượng Quốc gia Việt Nam | C5: PetroVietnam | D5: PVN | E5: Oil & gas | F5: Dầu khí | G5: PetroVietnam | H5: Parent | I5: =TRUE() -> TRUE | J5: 90991 | K5: 12585 | L5: 8648 | M5: 14599 | N5: 1865 | P5: =SUM(K5:O5) -> 37697
A6: 2 | B6: Tập đoàn Công nghiệp - Viễn thông Quân đội (Viettel) | C6: Viettel | D6: VIETTEL | E6: Technology & telecom | F6: Công nghệ - Viễn thông - Truyền thông | G6: Viettel | H6: Parent | I6: =TRUE() -> TRUE | J6: 42290 | P6: =SUM(K6:O6) -> 0
A7: 3 | B7: Tập đoàn Xăng dầu Việt Nam | C7: Petrolimex | D7: PLX | E7: Fuel distribution | F7: Xăng dầu - khí đốt | G7: Petrolimex | H7: Parent | I7: =TRUE() -> TRUE | J7: 30575 | K7: 3055 | L7: 6397 | M7: 727 | N7: 320 | P7: =SUM(K7:O7) -> 10499
A8: 4 | B8: Tập đoàn Công nghiệp Than - Khoáng sản Việt Nam | C8: Vinacomin | D8: VINACOMIN | E8: Coal & minerals | F8: Than, Khoáng sản | G8: Vinacomin | H8: Parent | I8: =TRUE() -> TRUE | J8: 24031 | K8: 3746 | L8: 2281 | M8: 1732 | O8: 423 | P8: =SUM(K8:O8) -> 8182
A9: 5 | B9: Tổng Công ty Thuốc lá Việt Nam - Công ty TNHH MTV | C9: Vinataba | D9: VINATABA | E9: Tobacco | F9: Thuốc lá | G9: — | H9: Standalone | I9: =TRUE() -> TRUE | J9: 22335 | K9: 3546 | M9: 418 | P9: =SUM(K9:O9) -> 3964
A10: 6 | B10: Tập đoàn Điện lực Việt Nam - Công ty TNHH MTV | C10: EVN | D10: EVN | E10: Power | F10: Điện năng | G10: EVN | H10: Parent | I10: =TRUE() -> TRUE | J10: 20891 | K10: 8367 | M10: 1201 | N10: 1163 | P10: =SUM(K10:O10) -> 10731
A11: 7 | B11: Công ty TNHH - Tổng Công ty Thăm dò Khai thác Dầu khí | C11: PVEP | D11: PVEP | E11: Oil & gas | F11: Dầu khí | G11: PetroVietnam | H11: Subsidiary | I11: =FALSE() -> FALSE | J11: 15105 | M11: 6685 | P11: =SUM(K11:O11) -> 6685
A12: 8 | B12: Công ty Cổ phần - Tổng Công ty Lọc Hóa dầu Việt Nam | C12: BSR | D12: BSR | E12: Oil & gas | F12: Dầu khí | G12: PetroVietnam | H12: Subsidiary | I12: =FALSE() -> FALSE | J12: 14531 | K12: 3499 | L12: 4673 | M12: 390 | P12: =SUM(K12:O12) -> 8562
A13: 9 | B13: Ngân hàng Thương mại cổ phần Ngoại thương Việt Nam | C13: Vietcombank | D13: VCB | E13: Banking | F13: Ngân hàng | G13: — | H13: Standalone | I13: =TRUE() -> TRUE | J13: 12494 | K13: 835 | M13: 9242 | P13: =SUM(K13:O13) -> 10077
A14: 10 | B14: Ngân hàng Thương mại cổ phần Đầu tư và Phát triển Việt Nam | C14: BIDV | D14: BID | E14: Banking | F14: Ngân hàng | G14: BIDV | H14: Parent | I14: =TRUE() -> TRUE | J14: 11374 | K14: 1430 | M14: 6768 | P14: =SUM(K14:O14) -> 8198
A15: 11 | B15: Tổng Công ty Dầu Việt Nam - CTCP | C15: PV Oil | D15: OIL | E15: Fuel distribution | F15: Xăng dầu - khí đốt | G15: PetroVietnam | H15: Subsidiary | I15: =FALSE() -> FALSE | J15: 11115 | K15: 1006 | L15: 1328 | M15: 124 | P15: =SUM(K15:O15) -> 2458
A16: 12 | B16: Tổng Công ty cổ phần Đầu tư Quốc tế Viettel | C16: Viettel Global | D16: VGI | E16: Technology & telecom | F16: Công nghệ - Viễn thông - Truyền thông | G16: Viettel | H16: Subsidiary | I16: =FALSE() -> FALSE | J16: 10657 | K16: 3781 | M16: 3191 | N16: 970 | P16: =SUM(K16:O16) -> 7942
A17: 13 | B17: Ngân hàng Thương mại Cổ phần Công thương Việt Nam | C17: Vietinbank | D17: CTG | E17: Banking | F17: Ngân hàng | G17: — | H17: Standalone | I17: =TRUE() -> TRUE | J17: 10057 | K17: 998 | M17: 7541 | P17: =SUM(K17:O17) -> 8539
A18: 14 | B18: Ngân hàng Thương mại cổ phần Quân đội | C18: MB | D18: MBB | E18: Banking | F18: Ngân hàng | G18: MB | H18: Parent | I18: =TRUE() -> TRUE | J18: 10004 | K18: 1105 | M18: 6518 | P18: =SUM(K18:O18) -> 7623
A19: 15 | B19: Tổng Công ty Đầu tư và Kinh doanh vốn Nhà nước | C19: SCIC | D19: SCIC | E19: Finance & investment | F19: Đầu tư | G19: — | H19: Standalone | I19: =TRUE() -> TRUE | J19: 8404 | M19: 384 | P19: =SUM(K19:O19) -> 384
A20: 16 | B20: Ngân hàng Nông nghiệp và Phát triển Nông thôn Việt Nam | C20: Agribank | D20: AGRIBANK | E20: Banking | F20: Ngân hàng | G20: — | H20: Standalone | I20: =TRUE() -> TRUE | J20: 7854 | K20: 763 | M20: 5658 | P20: =SUM(K20:O20) -> 6421
A21: 17 | B21: Tổng Công ty Khí Việt Nam-CTCP | C21: PV Gas | D21: GAS | E21: Oil & gas | F21: Dầu khí | G21: PetroVietnam | H21: Subsidiary | I21: =FALSE() -> FALSE | J21: 7278 | K21: 1934 | L21: 2141 | M21: 2403 | P21: =SUM(K21:O21) -> 6478
A22: 18 | B22: Công ty Đầu tư Tài chính Nhà nước T.P Hồ Chí Minh | C22: HFIC | D22: HFIC | E22: Finance & investment | F22: Đầu tư | G22: HFIC | H22: Parent | I22: =TRUE() -> TRUE | J22: 6794 | K22: 1441 | M22: 683 | N22: 500 | O22: 339 | P22: =SUM(K22:O22) -> 2963
A23: 19 | B23: Công ty TNHH MTV Xổ số kiến thiết Thành phố Hồ Chí Minh | C23: HCM City Lottery | D23: XSHCM | E23: Lottery | F23: Xổ số | G23: HFIC | H23: Subsidiary | I23: =FALSE() -> FALSE | J23: 6176 | K23: 1378 | M23: 498 | N23: 490 | P23: =SUM(K23:O23) -> 2366
A24: 20 | B24: Tập đoàn Bưu chính Viễn thông Việt Nam | C24: VNPT | D24: VNPT | E24: Technology & telecom | F24: Công nghệ - Viễn thông - Truyền thông | G24: — | H24: Standalone | I24: =TRUE() -> TRUE | J24: 6078 | P24: =SUM(K24:O24) -> 0
A25: 21 | B25: Tổng Công ty Phát điện 1 | C25: EVN Genco1 | D25: GENCO1 | E25: Power | F25: Điện năng | G25: EVN | H25: Subsidiary | I25: =FALSE() -> FALSE | J25: 5422 | K25: 3521 | M25: 237 | P25: =SUM(K25:O25) -> 3758
A26: 22 | B26: Tổng công ty Cảng hàng không Việt Nam - CTCP | C26: ACV | D26: ACV | E26: Aviation | F26: Hàng không | G26: — | H26: Standalone | I26: =TRUE() -> TRUE | J26: 4656 | K26: 211 | M26: 2582 | N26: 403 | O26: 149 | P26: =SUM(K26:O26) -> 3345
A27: 23 | B27: Tổng Công ty Khánh Việt | C27: Khatoco | D27: KHATOCO | E27: Tobacco | F27: Thuốc lá | G27: — | H27: Standalone | I27: =TRUE() -> TRUE | J27: 4292 | K27: 537 | L27: 78 | M27: 58 | P27: =SUM(K27:O27) -> 673
A28: 24 | B28: Tổng CTCP Bia - Rượu - Nước giải khát Hà Nội | C28: Habeco | D28: BHN | E28: Food & beverage | F28: Bia rượu | G28: — | H28: Standalone | I28: =TRUE() -> TRUE | J28: 4158 | K28: 613 | M28: 155 | P28: =SUM(K28:O28) -> 768
A29: 25 | B29: Công ty Cổ phần Viễn thông FPT | C29: FPT Telecom | D29: FOX | E29: Technology & telecom | F29: Công nghệ - Viễn thông - Truyền thông | G29: — | H29: Standalone | I29: =TRUE() -> TRUE | J29: 3945 | K29: 2580 | M29: 955 | N29: 296 | P29: =SUM(K29:O29) -> 3831
A30: 26 | B30: Tổng Công ty Công nghiệp Sài Gòn - TNHH Một thành viên | C30: CNS | D30: CNS | E30: Tobacco | F30: Thuốc lá | G30: — | H30: Standalone | I30: =TRUE() -> TRUE | J30: 3691 | K30: 421 | L30: 77 | M30: 107 | N30: 19 | P30: =SUM(K30:O30) -> 624
A31: 27 | B31: Tập đoàn Công nghiệp Cao su Việt Nam | C31: Vietnam Rubber Group | D31: GVR | E31: Chemicals & rubber | F31: Cao su, Bất động sản | G31: — | H31: Standalone | I31: =TRUE() -> TRUE | J31: 3413 | K31: 858 | M31: 1232 | N31: 162 | O31: 751 | P31: =SUM(K31:O31) -> 3003
A32: 28 | B32: Tổng Công ty Hàng không Việt Nam - CTCP | C32: Vietnam Airlines | D32: HVN | E32: Aviation | F32: Hàng không | G32: — | H32: Standalone | I32: =TRUE() -> TRUE | J32: 3291 | K32: 969 | M32: 416 | N32: 874 | P32: =SUM(K32:O32) -> 2259
A33: 29 | B33: Sở Giao dịch Chứng khoán Việt Nam | C33: Vietnam Exchange | D33: VNEX | E33: Finance & investment | F33: Tài chính | G33: Vietnam Exchange | H33: Parent | I33: =TRUE() -> TRUE | J33: 3283 | K33: 6 | M33: 659 | P33: =SUM(K33:O33) -> 665
A34: 30 | B34: Tổng Công ty Cấp nước Sài Gòn | C34: Sawaco | D34: SAWACO | E34: Water | F34: Cấp thoát nước | G34: — | H34: Standalone | I34: =TRUE() -> TRUE | J34: 3179 | K34: 232 | M34: 337 | P34: =SUM(K34:O34) -> 569
A35: 31 | B35: Công ty TNHH MTV - Tổng Công ty Tân Cảng Sài Gòn | C35: Saigon New Port/SNP | D35: SNP | E35: Transport & logistics | F35: Vận tải - Logistics | G35: — | H35: Standalone | I35: =TRUE() -> TRUE | J35: 3000 | P35: =SUM(K35:O35) -> 0
A36: 32 | B36: Tổng Công ty Quản lý bay Việt Nam | C36: VATM | D36: VATM | E36: Aviation | F36: Hàng không | G36: — | H36: Standalone | I36: =TRUE() -> TRUE | J36: 2948 | M36: 358 | P36: =SUM(K36:O36) -> 358
A37: 33 | B37: CÔNG TY TNHH MTV XỔ SỐ KIẾN THIẾT LONG AN | C37: Long An Lottery | D37: XSLA | E37: Lottery | F37: Xổ số | G37: — | H37: Standalone | I37: =TRUE() -> TRUE | J37: 2797 | P37: =SUM(K37:O37) -> 0
A38: 34 | B38: CÔNG TY TNHH MTV XỔ SỐ KIẾN THIẾT BẠC LIÊU | C38: Bạc Liêu Lottery | D38: XSBL | E38: Lottery | F38: Xổ số | G38: — | H38: Standalone | I38: =TRUE() -> TRUE | J38: 2751 | K38: 640 | M38: 207 | P38: =SUM(K38:O38) -> 847
A39: 35 | B39: CÔNG TY TNHH MTV XỔ SỐ KIẾN THIẾT BÌNH DƯƠNG | C39: Bình Dương Lottery | D39: XSBINHDUONG | E39: Lottery | F39: Xổ số | G39: — | H39: Standalone | I39: =TRUE() -> TRUE | J39: 2749 | K39: 630 | M39: 212 | P39: =SUM(K39:O39) -> 842
A40: 36 | B40: Công ty TNHH MTV Xổ Số Kiến Thiết Bến Tre | C40: Bến Tre Lottery | D40: XSBENTRE | E40: Lottery | F40: Xổ số | G40: — | H40: Standalone | I40: =TRUE() -> TRUE | J40: 2738 | K40: 643 | M40: 207 | P40: =SUM(K40:O40) -> 850
A41: 37 | B41: Công ty TNHH MTV Xổ số kiến thiết Cà Mau | C41: Cà Mau Lottery | D41: XSCM | E41: Lottery | F41: Xổ số | G41: — | H41: Standalone | I41: =TRUE() -> TRUE | J41: 2721 | K41: 640 | M41: 175 | P41: =SUM(K41:O41) -> 815
...

Sheet STATE 100 groups
A1: Corporate groups inside STATE 100
A4: Corporate group | B4: Entries ranked | C4: Parent payment | D4: Subsidiaries ranked (memo) | E4: Share of STATE 100
A5: PetroVietnam | B5: 11 | C5: 90991 | D5: 54021 | E5: =C5/'STATE 100 firms'!$J$107 -> 0.21367666
A6: Viettel | B6: 4 | C6: 42290 | D6: 12696 | E6: =C6/'STATE 100 firms'!$J$107 -> 0.099310766
A7: Petrolimex | B7: 3 | C7: 30575 | D7: 1289 | E7: =C7/'STATE 100 firms'!$J$107 -> 0.07180011
A8: Vinacomin | B8: 4 | C8: 24031 | D8: 3418 | E8: =C8/'STATE 100 firms'!$J$107 -> 0.056432656
A9: EVN | B9: 8 | C9: 20891 | D9: 11305 | E9: =C9/'STATE 100 firms'!$J$107 -> 0.049058908
A10: BIDV | B10: 2 | C10: 11374 | D10: 513 | E10: =C10/'STATE 100 firms'!$J$107 -> 0.026709876
A11: MB | B11: 2 | C11: 10004 | D11: 834 | E11: =C11/'STATE 100 firms'!$J$107 -> 0.023492667
A12: HFIC | B12: 2 | C12: 6794 | D12: 6176 | E12: =C12/'STATE 100 firms'!$J$107 -> 0.015954536
A13: Vietnam Exchange | B13: 2 | C13: 3283 | D13: 531 | E13: =C13/'STATE 100 firms'!$J$107 -> 0.0077095589
A14: Vinachem | B14: 2 | C14: 2268 | D14: 496 | E14: =C14/'STATE 100 firms'!$J$107 -> 0.0053260066
A15: Bao Viet | B15: 2 | C15: 1817 | D15: 946 | E15: =C15/'STATE 100 firms'!$J$107 -> 0.0042669109
A16: Groups combined | B16: =SUM(B5:B15) -> 42 | C16: =SUM(C5:C15) -> 244318 | D16: =SUM(D5:D15) -> 92225
A17: Ungrouped, single-entity SOEs | B17: 58 | C17: 181517

Sheet Year on year
A1: Financial year 2024 against financial year 2025
A2: FY2024 from the VNTAX 200 list published in 2025; FY2025 from the list published in 2026. Same 200-firm cut-off, different constituents.
A4: Ownership | B4: FY2024 firms | C4: FY2024 (VND bn) | D4: FY2024 share | E4: FY2025 firms | F4: FY2025 (VND bn) | G4: FY2025 share | H4: Change
A5: State-owned (SOE) | B5: 75 | C5: 433090 | D5: =C5/$C$8 -> 0.54352164 | E5: 74 | F5: 445558 | G5: =F5/$F$8 -> 0.45039798 | H5: =F5/C5-1 -> 0.028788474
A6: Domestic private | B6: 101 | C6: 248990 | D6: =C6/$C$8 -> 0.31247882 | E6: 99 | F6: 390311 | G6: =F6/$F$8 -> 0.39455084 | H6: =F6/C6-1 -> 0.56757701
A7: Foreign-invested (FDI) | B7: 24 | C7: 114742 | D7: =C7/$C$8 -> 0.14399954 | E7: 27 | F7: 153385 | G7: =F7/$F$8 -> 0.15505118 | H7: =F7/C7-1 -> 0.33678165
A8: TOTAL | B8: =SUM(B5:B7) -> 200 | C8: =SUM(C5:C7) -> 796822 | D8: =C8/$C$8 -> 1 | E8: =SUM(E5:E7) -> 200 | F8: =SUM(F5:F7) -> 989254 | G8: =F8/$F$8 -> 1 | H8: =F8/C8-1 -> 0.24149936
A10: The state share falls from 54% to 45% between the two years. Almost all of the swing is one firm: Vingroup goes
A11: from VND 56,163 bn to VND 148,773 bn, of which VND 93,813 bn is land and land rent.
